Workbook

Sheet Raw Data
A1: Transaction_ID | B1: Customer_ID | C1: Transaction_Date | D1: Product | E1: Channel | F1: Amount | G1: Quantity | H1: Country
A2: T354568 | B2: C4347 | C2: 44870 | D2: Renewal | E2: Phone | F2: 321.99 | G2: 7 | H2: Germany
A3: T125103 | B3: C2127 | C3: 45907 | D3: Subscription | E3: Phone | F3: 841.44 | G3: 10 | H3: India
A4: T279217 | B4: C9937 | C4: 45106 | D4: One-time Purchase | E4: Partner | G4: 1 | H4: UK
A5: T365841 | B5: C2294 | C5: 45321 | D5: Renewal | E5: Phone | F5: 1781.98 | G5: 7 | H5: USA
A6: T420901 | B6: C8110 | C6: 45189 | D6: Renewal | E6: Phone | G6: 9 | H6: Canada
A7: T237240 | B7: C1498 | C7: 45231 | D7: Renewal | E7: Online | G7: 1 | H7: Germany
A8: T234320 | B8: C1951 | C8: 45749 | D8: Renewal | E8: Phone | F8: 586.43 | G8: 2 | H8: India
A9: T156561 | B9: C3285 | C9: 45600 | D9: Addon | E9: Online | F9: 1451.06 | G9: 6 | H9: USA
A10: T723456 | B10: C4470 | C10: 45239 | D10: Subscription | E10: Partner | F10: 523.62 | G10: 5 | H10: Germany
A11: T502295 | B11: C1873 | C11: 45525 | D11: Addon | E11: Partner | G11: 4 | H11: India
A12: T654745 | B12: C9201 | C12: 45893 | D12: Subscription | E12: Partner | F12: 1009.09 | G12: 9 | H12: UK
A13: T868523 | B13: C9122 | C13: 45579 | D13: Renewal | E13: Partner | F13: 1758.15 | G13: 7 | H13: India
A14: T967011 | B14: C8331 | C14: 45745 | D14: Renewal | E14: Phone | F14: 1415.78 | G14: 7 | H14: UK
A15: T693785 | B15: C3307 | C15: 45222 | D15: One-time Purchase | E15: Partner | F15: 909.74 | G15: 8 | H15: Canada
A16: T687727 | B16: C2156 | C16: 45153 | D16: Addon | E16: Phone | F16: 1793.66 | G16: 8 | H16: India
A17: T330514 | B17: C2754 | C17: 45202 | D17: Renewal | E17: Online | F17: 692.81 | G17: 9 | H17: India
A18: T563812 | B18: C5366 | C18: 45794 | D18: One-time Purchase | E18: In-Store | F18: 995.75 | G18: 5 | H18: Germany
A19: T168897 | B19: C2219 | C19: 45511 | D19: Subscription | E19: Partner | F19: 1977.14 | G19: 6 | H19: USA
A20: T956489 | B20: C5377 | C20: 45662 | D20: One-time Purchase | E20: Online | F20: 125.27 | G20: 3 | H20: UK
A21: T378931 | B21: C1106 | C21: 45605 | D21: Subscription | E21: online | F21: 391.56 | G21: 1 | H21: Germany
A22: T410819 | B22: C9404 | C22: 45932 | D22: Addon | E22: online | F22: 1092.7 | G22: 7 | H22: India
A23: T651516 | B23: C6182 | C23: 45086 | D23: Addon | E23: Phone | F23: 133.05 | G23: 10 | H23: USA
... A25: T862295 | B25: C5749 | C25: 45489 | D25: One-time Purchase | E25: online | F25: 1992.18 | G25: 1 | H25: India
A26: T122805 | B26: C2644 | C26: 45097 | D26: Addon | E26: online | G26: 2 | H26: USA
A27: T603868 | B27: C6933 | C27: 45438 | D27: Addon | E27: Phone | F27: 1085.11 | G27: 5 | H27: Canada
A28: T166755 | B28: C9027 | C28: 45180 | D28: Addon | E28: Phone | F28: 1617.55 | G28: 10 | H28: USA
A29: T303296 | B29: C7839 | C29: 45377 | D29: One-time Purchase | E29: In-Store | F29: 1258.31 | G29: 3 | H29: USA
A30: T623654 | B30: C5469 | C30: 45308 | D30: Renewal | E30: Online | F30: 1848.54 | G30: 3 | H30: Canada
A31: T594099 | B31: C6711 | C31: 45778 | D31: Renewal | E31: Phone | F31: 1059.17 | G31: 4 | H31: Canada
A32: T493113 | B32: C3662 | C32: 45261 | D32: Subscription | E32: Phone | F32: 345.91 | G32: 1 | H32: India
A33: T523372 | B33: C5956 | C33: 45555 | D33: Subscription | E33: Phone | F33: 1958.97 | G33: 4 | H33: Germany
A34: T820292 | B34: C8914 | C34: 44977 | D34: One-time Purchase | E34: online | F34: 1713.36 | G34: 6 | H34: UK
A35: T597069 | B35: C8374 | C35: 45120 | D35: Renewal | E35: Phone | F35: 292.39 | G35: 7 | H35: India
A36: T583061 | B36: C4988 | C36: 45058 | D36: Renewal | E36: Phone | G36: 7 | H36: Canada
A37: T127012 | B37: C7287 | C37: 45592 | D37: Subscription | E37: Online | F37: 196.83 | G37: 7 | H37: Germany
A38: T718690 | B38: C4719 | C38: 44857 | D38: Addon | E38: In-Store | F38: 486.79 | H38: Canada
A39: T652859 | B39: C5208 | C39: 45811 | D39: Renewal | E39: Partner | F39: 1341.07 | G39: 9 | H39: Canada
A40: T856681 | B40: C7581 | C40: 45378 | D40: Addon | E40: Online | F40: 779.64 | H40: India
A41: T965791 | B41: C9973 | C41: 45579 | D41: One-time Purchase | E41: Online | F41: 1933.12 | G41: 6 | H41: USA
...

Sheet ✅ Cleaned Data
A1: Transaction_ID | B1: Customer_ID | C1: Transaction_Date | D1: Product | E1: Channel | F1: Amount | G1: Quantity | H1: Country
A2: T354568 | B2: C4347 | C2: 44870 | D2: Renewal | E2: Phone | F2: 321.99 | G2: 7 | H2: Germany
A3: T125103 | B3: C2127 | C3: 45907 | D3: Subscription | E3: Phone | F3: 841.44 | G3: 10 | H3: India
A4: T279217 | B4: C9937 | C4: 45106 | D4: One-Time Purchase | E4: Partner | F4: 382.60857 | G4: 1 | H4: Uk
A5: T365841 | B5: C2294 | C5: 45321 | D5: Renewal | E5: Phone | F5: 1781.98 | G5: 7 | H5: Usa
A6: T420901 | B6: C8110 | C6: 45189 | D6: Renewal | E6: Phone | F6: 201.24 | G6: 9 | H6: Canada
A7: T237240 | B7: C1498 | C7: 45231 | D7: Renewal | E7: Online | F7: 160.27333 | G7: 1 | H7: Germany
A8: T234320 | B8: C1951 | C8: 45749 | D8: Renewal | E8: Phone | F8: 586.43 | G8: 2 | H8: India
A9: T156561 | B9: C3285 | C9: 45600 | D9: Addon | E9: Online | F9: 1451.06 | G9: 6 | H9: Usa
A10: T723456 | B10: C4470 | C10: 45239 | D10: Subscription | E10: Partner | F10: 523.62 | G10: 5 | H10: Germany
A11: T502295 | B11: C1873 | C11: 45525 | D11: Addon | E11: Partner | F11: 993.7175 | G11: 4 | H11: India
A12: T654745 | B12: C9201 | C12: 45893 | D12: Subscription | E12: Partner | F12: 1009.09 | G12: 9 | H12: Uk
A13: T868523 | B13: C9122 | C13: 45579 | D13: Renewal | E13: Partner | F13: 1758.15 | G13: 7 | H13: India
... A2001: T627151 | B2001: C2434 | C2001: 44989 | D2001: Renewal | E2001: Online | F2001: 792.6 | G2001: 2 | H2001: Uk

Sheet Dashboard
A1: 📊 لوحة معلومات المبيعات - Sales Dashboard
A3: 💰 إجمالي المبيعات الكلي | C3: 📝 عدد المعاملات | E3: 📈 متوسط قيمة المعاملة
A4: =SUM('✅ Cleaned Data'!F:F) -> 1910562.8 | C4: =COUNTA('✅ Cleaned Data'!A:A)-1 -> 2000 | E4: =AVERAGE('✅ Cleaned Data'!F:F) -> 955.28141
A6: 🏆 أفضل المنتجات مبيعاً - Top Products by Sales
A7: Rank | B7: Product Name | C7: Total Quantity | D7: Total Sales | E7: % of Total
A8: ='Top Products'!A4 -> 1 | B8: ='Top Products'!B4 -> Renewal | C8: ='Top Products'!C4 -> 2914 | D8: ='Top Products'!D4 -> 504355.12 | E8: ='Top Products'!E4 -> 0.26398249
A9: ='Top Products'!A5 -> 2 | B9: ='Top Products'!B5 -> Addon | C9: ='Top Products'!C5 -> 2743 | D9: ='Top Products'!D5 -> 501307.87 | E9: ='Top Products'!E5 -> 0.26238754
A10: ='Top Products'!A6 -> 3 | B10: ='Top Products'!B6 -> One-Time Purchase | C10: ='Top Products'!C6 -> 2587 | D10: ='Top Products'!D6 -> 477395.68 | E10: ='Top Products'!E6 -> 0.24987175
A11: ='Top Products'!A7 -> 4 | B11: ='Top Products'!B7 -> Subscription | C11: ='Top Products'!C7 -> 2550 | D11: ='Top Products'!D7 -> 427504.14 | E11: ='Top Products'!E7 -> 0.22375822
A14: 📈 المبيعات الشهرية - Monthly Sales Trend

Sheet Sales by Month
A1: 📊 لوحة معلومات المبيعات - Sales Dashboard
A3: Year | B3: Month | C3: Month Name | D3: Total Sales | E3: Transaction Count
A4: 2022 | B4: 10 | C4: October | D4: 12152.932 | E4: 14
A5: 2022 | B5: 11 | C5: November | D5: 50837.893 | E5: 62
A6: 2022 | B6: 12 | C6: December | D6: 50054.51 | E6: 54
A7: 2023 | B7: 1 | C7: January | D7: 48145.152 | E7: 47
A8: 2023 | B8: 2 | C8: February | D8: 58288.862 | E8: 50
A9: 2023 | B9: 3 | C9: March | D9: 54507.36 | E9: 54
A10: 2023 | B10: 4 | C10: April | D10: 43181.426 | E10: 44
A11: 2023 | B11: 5 | C11: May | D11: 62066.105 | E11: 62
A12: 2023 | B12: 6 | C12: June | D12: 46791.352 | E12: 54
A13: 2023 | B13: 7 | C13: July | D13: 51170.846 | E13: 51
A14: 2023 | B14: 8 | C14: August | D14: 69288.617 | E14: 67
A15: 2023 | B15: 9 | C15: September | D15: 44433.931 | E15: 45
... A40: 2025 | B40: 10 | C40: October | D40: 40325.626 | E40: 43
C41: TOTAL | D41: =SUM(D4:D40) -> 1910562.8 | E41: =SUM(E4:E40) -> 2000

Sheet Top Products
A1: 📊 لوحة معلومات المبيعات - Sales Dashboard
A3: Rank | B3: Product Name | C3: Total Quantity | D3: Total Sales | E3: % of Total Sales
A4: 1 | B4: Renewal | C4: 2914 | D4: 504355.12 | E4: 0.26398249
A5: 2 | B5: Addon | C5: 2743 | D5: 501307.87 | E5: 0.26238754
A6: 3 | B6: One-Time Purchase | C6: 2587 | D6: 477395.68 | E6: 0.24987175
A7: 4 | B7: Subscription | C7: 2550 | D7: 427504.14 | E7: 0.22375822
B8: TOTAL | C8: =SUM(C4:C7) -> 10794 | D8: =SUM(D4:D7) -> 1910562.8 | E8: =SUM(E4:E7) -> 1
